<?xml version="1.0" encoding="utf-8"?>
<!-- This URDF was automatically created by SolidWorks to URDF Exporter! Originally created by Stephen Brawner (brawner@gmail.com) 
     Commit Version: 1.6.0-4-g7f85cfe  Build Version: 1.6.7995.38578
     For more information, please see http://wiki.ros.org/sw_urdf_exporter -->
<robot
  name="urdf_v16">
  <link
    name="base">
    <inertial>
      <origin
        xyz="-0.0389201994223138 0.0606404283501684 0.0288009133507181"
        rpy="0 0 0" />
      <mass
        value="1.80445503906733" />
      <inertia
        ixx="0.00557261131259849"
        ixy="1.30566151455957E-06"
        ixz="-0.000539475235711391"
        iyy="0.0133501948716485"
        iyz="4.50573070557487E-07"
        izz="0.0165394809218581" />
    </inertial>
    <visual>
      <origin
        xyz="0 0 0"
        rpy="0 0 0" />
      <geometry>
        <mesh
          filename="package://urdf_v16/meshes/base.STL" />
      </geometry>
      <material
        name="">
        <color
          rgba="0.792156862745098 0.819607843137255 0.933333333333333 1" />
      </material>
    </visual>
    <collision>
      <origin
        xyz="0 0 0"
        rpy="0 0 0" />
      <geometry>
        <mesh
          filename="package://urdf_v16/meshes/base.STL" />
      </geometry>
    </collision>
  </link>
  <link
    name="base_link ">
    <inertial>
      <origin
        xyz="-3.64068112765903E-05 -0.0118678758824738 0.0827015339279813"
        rpy="0 0 0" />
      <mass
        value="2.09089508032486" />
      <inertia
        ixx="0.013613386163526"
        ixy="4.81772898626971E-06"
        ixz="-8.58975907907224E-06"
        iyy="0.00966545436281291"
        iyz="-0.000408881288625665"
        izz="0.00889732682523512" />
    </inertial>
    <visual>
      <origin
        xyz="0 0 0"
        rpy="0 0 0" />
      <geometry>
        <mesh
          filename="package://urdf_v16/meshes/base_link .STL" />
      </geometry>
      <material
        name="">
        <color
          rgba="0.792156862745098 0.819607843137255 0.933333333333333 1" />
      </material>
    </visual>
    <collision>
      <origin
        xyz="0 0 0"
        rpy="0 0 0" />
      <geometry>
        <mesh
          filename="package://urdf_v16/meshes/base_link .STL" />
      </geometry>
    </collision>
    <ignore_collision link="base"/>
  </link>
  <joint
    name="joint_1"
    type="continuous">
    <origin
      xyz="0.0046192 0.060628 0.080563"
      rpy="0 0 0" />
    <parent
      link="base" />
    <child
      link="base_link " />
    <axis
      xyz="0 0 1" />
  </joint>
  <link
    name="shoulder">
    <inertial>
      <origin
        xyz="0.000114735555256318 0.0016461882487272 0.0799416450271098"
        rpy="0 0 0" />
      <mass
        value="1.93113222457088" />
      <inertia
        ixx="0.01708627154071"
        ixy="3.41459798496628E-06"
        ixz="-5.32606176023139E-07"
        iyy="0.0162697586704728"
        iyz="-0.000123095839040227"
        izz="0.0035998842492619" />
    </inertial>
    <visual>
      <origin
        xyz="0 0 0"
        rpy="0 0 0" />
      <geometry>
        <mesh
          filename="package://urdf_v16/meshes/shoulder.STL" />
      </geometry>
      <material
        name="">
        <color
          rgba="0.792156862745098 0.819607843137255 0.933333333333333 1" />
      </material>
    </visual>
    <collision>
      <origin
        xyz="0 0 0"
        rpy="0 0 0" />
      <geometry>
        <mesh
          filename="package://urdf_v16/meshes/shoulder.STL" />
      </geometry>
    </collision>
  </link>
  <joint
    name="joint_2"
    type="continuous">
    <origin
      xyz="0 0 0.16694"
      rpy="0 -0.0044397 0" />
    <parent
      link="base_link " />
    <child
      link="shoulder" />
    <axis
      xyz="0 1 0" />
  </joint>
  <link
    name="elbow">
    <inertial>
      <origin
        xyz="-7.45904489801719E-05 -0.000200828334464331 0.0430510825590724"
        rpy="0 0 0" />
      <mass
        value="0.777952609021586" />
      <inertia
        ixx="0.00228138056803775"
        ixy="6.75259481605935E-08"
        ixz="-6.02427649398722E-07"
        iyy="0.00230093031518272"
        iyz="-3.06257703779093E-05"
        izz="0.000730694022246996" />
    </inertial>
    <visual>
      <origin
        xyz="0 0 0"
        rpy="0 0 0" />
      <geometry>
        <mesh
          filename="package://urdf_v16/meshes/elbow.STL" />
      </geometry>
      <material
        name="">
        <color
          rgba="0.792156862745098 0.819607843137255 0.933333333333333 1" />
      </material>
    </visual>
    <collision>
      <origin
        xyz="0 0 0"
        rpy="0 0 0" />
      <geometry>
        <mesh
          filename="package://urdf_v16/meshes/elbow.STL" />
      </geometry>
    </collision>
  </link>
  <joint
    name="joint_3"
    type="continuous">
    <origin
      xyz="0 0 0.22112"
      rpy="0 0.0044397 0" />
    <parent
      link="shoulder" />
    <child
      link="elbow" />
    <axis
      xyz="0 1 0" />
  </joint>
  <link
    name="wrist_1">
    <inertial>
      <origin
        xyz="0.000153341839407795 0.00254377249979626 0.0552077416540102"
        rpy="0 0 0" />
      <mass
        value="0.336033452724269" />
      <inertia
        ixx="0.000698588486758794"
        ixy="-1.06886801069468E-06"
        ixz="4.79927277974197E-06"
        iyy="0.000573509249244311"
        iyz="1.12103478727962E-05"
        izz="0.000348806449824706" />
    </inertial>
    <visual>
      <origin
        xyz="0 0 0"
        rpy="0 0 0" />
      <geometry>
        <mesh
          filename="package://urdf_v16/meshes/wrist_1.STL" />
      </geometry>
      <material
        name="">
        <color
          rgba="0.792156862745098 0.819607843137255 0.933333333333333 1" />
      </material>
    </visual>
    <collision>
      <origin
        xyz="0 0 0"
        rpy="0 0 0" />
      <geometry>
        <mesh
          filename="package://urdf_v16/meshes/wrist_1.STL" />
      </geometry>
    </collision>
  </link>
  <joint
    name="joint_4"
    type="continuous">
    <origin
      xyz="0 0.000501 0.12994"
      rpy="0 0 0" />
    <parent
      link="elbow" />
    <child
      link="wrist_1" />
    <axis
      xyz="0 0 1" />
  </joint>
  <link
    name="wrist_2">
    <inertial>
      <origin
        xyz="1.77926530077199E-05 0.000385812865379087 0.00382819991882888"
        rpy="0 0 0" />
      <mass
        value="0.158624033379915" />
      <inertia
        ixx="8.93595815588662E-05"
        ixy="-2.61047265879977E-09"
        ixz="-6.69970075351791E-08"
        iyy="0.000106318553763207"
        iyz="-6.19881915619726E-07"
        izz="7.5097766833281E-05" />
    </inertial>
    <visual>
      <origin
        xyz="0 0 0"
        rpy="0 0 0" />
      <geometry>
        <mesh
          filename="package://urdf_v16/meshes/wrist_2.STL" />
      </geometry>
      <material
        name="">
        <color
          rgba="0.792156862745098 0.819607843137255 0.933333333333333 1" />
      </material>
    </visual>
    <collision>
      <origin
        xyz="0 0 0"
        rpy="0 0 0" />
      <geometry>
        <mesh
          filename="package://urdf_v16/meshes/wrist_2.STL" />
      </geometry>
    </collision>
  </link>
  <joint
    name="joint_5"
    type="continuous">
    <origin
      xyz="0 0 0.098961"
      rpy="0 0 0" />
    <parent
      link="wrist_1" />
    <child
      link="wrist_2" />
    <axis
      xyz="0 1 0" />
  </joint>
  <link
    name="gripper_base">
    <inertial>
      <origin
        xyz="0.0144248332652381 -0.00140943468206361 0.729409570686998"
        rpy="0 0 0" />
      <mass
        value="0.0669550622960312" />
      <inertia
        ixx="2.24885107005276E-05"
        ixy="2.35779600509359E-06"
        ixz="-2.87441674029786E-06"
        iyy="3.18452559004708E-05"
        iyz="3.57683917662539E-07"
        izz="3.67649419263123E-05" />
    </inertial>
    <visual>
      <origin
        xyz="0 0 0"
        rpy="0 0 0" />
      <geometry>
        <mesh
          filename="package://urdf_v16/meshes/gripper_base.STL" />
      </geometry>
      <material
        name="">
        <color
          rgba="0.792156862745098 0.819607843137255 0.933333333333333 1" />
      </material>
    </visual>
    <collision>
      <origin
        xyz="0 0 0"
        rpy="0 0 0" />
      <geometry>
        <mesh
          filename="package://urdf_v16/meshes/gripper_base.STL" />
      </geometry>
    </collision>
  </link>
  <joint
    name="joint_6"
    type="fixed">
    <origin
      xyz="0.00098171 -0.000501 -0.66696"
      rpy="0 0 0" />
    <parent
      link="wrist_2" />
    <child
      link="gripper_base" />
    <axis
      xyz="0 0 0" />
  </joint>
  <link
    name="servo_gear1">
    <inertial>
      <origin
        xyz="-0.0100576763756515 -0.00793429336823925 -0.000922276940248268"
        rpy="0 0 0" />
      <mass
        value="0.00438273139903777" />
      <inertia
        ixx="9.89317510651496E-07"
        ixy="1.98722680590235E-10"
        ixz="-7.64270919579872E-10"
        iyy="1.8900131850761E-07"
        iyz="4.23805101340853E-08"
        izz="8.26162926123892E-07" />
    </inertial>
    <visual>
      <origin
        xyz="0 0 0"
        rpy="0 0 0" />
      <geometry>
        <mesh
          filename="package://urdf_v16/meshes/servo_gear1.STL" />
      </geometry>
      <material
        name="">
        <color
          rgba="0.792156862745098 0.819607843137255 0.933333333333333 1" />
      </material>
    </visual>
    <collision>
      <origin
        xyz="0 0 0"
        rpy="0 0 0" />
      <geometry>
        <mesh
          filename="package://urdf_v16/meshes/servo_gear1.STL" />
      </geometry>
    </collision>
  </link>
  <joint
    name="joint_7"
    type="continuous">
    <origin
      xyz="0.0093777 -0.013452 0.73231"
      rpy="-1.5563 0.0046149 0.0046825" />
    <parent
      link="gripper_base" />
    <child
      link="servo_gear1" />
    <axis
      xyz="0.99999 0 -0.0046829" />
  </joint>
  <link
    name="leg1">
    <inertial>
      <origin
        xyz="0.00929593624657088 -0.00070323766853897 0.04759195429348"
        rpy="0 0 0" />
      <mass
        value="0.0106754375169454" />
      <inertia
        ixx="4.10221567193055E-06"
        ixy="-1.70840076438384E-09"
        ixz="-9.73747882338398E-09"
        iyy="4.17675163334443E-06"
        iyz="-6.39775284497913E-07"
        izz="5.77185004785099E-07" />
    </inertial>
    <visual>
      <origin
        xyz="0 0 0"
        rpy="0 0 0" />
      <geometry>
        <mesh
          filename="package://urdf_v16/meshes/leg1.STL" />
      </geometry>
      <material
        name="">
        <color
          rgba="0.792156862745098 0.819607843137255 0.933333333333333 1" />
      </material>
    </visual>
    <collision>
      <origin
        xyz="0 0 0"
        rpy="0 0 0" />
      <geometry>
        <mesh
          filename="package://urdf_v16/meshes/leg1.STL" />
      </geometry>
    </collision>
  </link>
  <joint
    name="jleg1"
    type="fixed">
    <origin
      xyz="-0.019057 -0.019896 0.0073322"
      rpy="1.5563 0.0046149 -0.0046825" />
    <parent
      link="servo_gear1" />
    <child
      link="leg1" />
    <axis
      xyz="0.99999 0 -0.0046829" />
  </joint>
  <link
    name="servo_gear2">
    <inertial>
      <origin
        xyz="4.90327258335643E-05 -0.0079342933183536 -0.000922776653681345"
        rpy="0 0 0" />
      <mass
        value="0.00438273139817732" />
      <inertia
        ixx="9.89317507891527E-07"
        ixy="1.98725319420247E-10"
        ixz="-7.64271453185175E-10"
        iyy="1.8900131821962E-07"
        iyz="4.23805083000154E-08"
        izz="8.26162923689625E-07" />
    </inertial>
    <visual>
      <origin
        xyz="0 0 0"
        rpy="0 0 0" />
      <geometry>
        <mesh
          filename="package://urdf_v16/meshes/servo_gear2.STL" />
      </geometry>
      <material
        name="">
        <color
          rgba="0.792156862745098 0.819607843137255 0.933333333333333 1" />
      </material>
    </visual>
    <collision>
      <origin
        xyz="0 0 0"
        rpy="0 0 0" />
      <geometry>
        <mesh
          filename="package://urdf_v16/meshes/servo_gear2.STL" />
      </geometry>
    </collision>
    <ignore_collision link="servo_gear1"/>
  </link>
  <joint
    name="joint_8"
    type="continuous">
    <origin
      xyz="-0.00062209 0.014501 0.73236"
      rpy="-1.5563 -0.0047509 -3.1369" />
    <parent
      link="gripper_base" />
    <child
      link="servo_gear2" />
    <axis
      xyz="0.99999 0 -0.0046829" />
    <mimic
      joint="joint_7"
      multiplier="1"
      offset="0" />
  </joint>
  <link
    name="leg2">
    <inertial>
      <origin
        xyz="-0.00877865438593095 -0.0147032394404991 0.0476765976677737"
        rpy="0 0 0" />
      <mass
        value="0.0106754461770056" />
      <inertia
        ixx="4.10221667015715E-06"
        ixy="-1.70826774106503E-09"
        ixz="-9.73784470972599E-09"
        iyy="4.17675215863974E-06"
        iyz="-6.39775026488929E-07"
        izz="5.77185107952736E-07" />
    </inertial>
    <visual>
      <origin
        xyz="0 0 0"
        rpy="0 0 0" />
      <geometry>
        <mesh
          filename="package://urdf_v16/meshes/leg2.STL" />
      </geometry>
      <material
        name="">
        <color
          rgba="0.792156862745098 0.819607843137255 0.933333333333333 1" />
      </material>
    </visual>
    <collision>
      <origin
        xyz="0 0 0"
        rpy="0 0 0" />
      <geometry>
        <mesh
          filename="package://urdf_v16/meshes/leg2.STL" />
      </geometry>
    </collision>
  </link>
  <joint
    name="jleg2"
    type="fixed">
    <origin
      xyz="0.0091903 -0.019693 0.021245"
      rpy="1.5563 0.0046149 -0.0046825" />
    <parent
      link="servo_gear2" />
    <child
      link="leg2" />
    <axis
      xyz="0 0 0" />
  </joint>
</robot>
